Workbook

Sheet Resumé
A1: BESS ved Ringkøbing Fjernvarme: tidlig investeringsberegning
A2: Udarbejdet 13.10.2026 til Kristian Hautorp. Status: TIL GODKENDELSE. Tidlig skrivebordsberegning uden data fra Ringkøbing Fjernvarme (RFV), uden tilbud og uden afklaring med netselskab og Skattestyrelsen.
A4: Nøgletal | B4: Pessimistisk | C4: Base | D4: Optimistisk
A5: Effekt (MW) | B5: =Pessimistisk!$B$5 -> 10 | C5: =Base!$B$5 -> 10 | D5: =Optimistisk!$B$5 -> 10
A6: Varighed (timer) | B6: =Pessimistisk!$B$6 -> 2 | C6: =Base!$B$6 -> 2 | D6: =Optimistisk!$B$6 -> 2
A7: Samlet investering (EUR) | B7: =Pessimistisk!$B$86 -> 8200000 | C7: =Base!$B$86 -> 6250000 | D7: =Optimistisk!$B$86 -> 5150000
A8: Investering pr. kWh (EUR) | B8: =Pessimistisk!$B$87 -> 410 | C8: =Base!$B$87 -> 312.5 | D8: =Optimistisk!$B$87 -> 257.5
A9: Investering pr. MW (EUR) | B9: =Pessimistisk!$B$88 -> 820000 | C9: =Base!$B$88 -> 625000 | D9: =Optimistisk!$B$88 -> 515000
A10: Markedsindtægt år 1 pr. MW (EUR) | B10: =Pessimistisk!$B$89 -> 62209.301 | C10: =Base!$B$89 -> 102775.34 | D10: =Optimistisk!$B$89 -> 172202.52
A11: EBITDA år 1 (EUR) | B11: =Pessimistisk!$B$90 -> -38032.217 | C11: =Base!$B$90 -> 526633.09 | D11: =Optimistisk!$B$90 -> 1288032
A12: EBITDA år 1 / investering | B12: =Pessimistisk!$B$92 -> -0.0046380752 | C12: =Base!$B$92 -> 0.084261294 | D12: =Optimistisk!$B$92 -> 0.2501033
A13: IRR før skat (ugearet) | B13: =Pessimistisk!$B$82 -> negativ | C13: =Base!$B$82 -> -0.0065111185 | D13: =Optimistisk!$B$82 -> 0.23418177
A14: IRR efter skat (ugearet) | B14: =Pessimistisk!$B$83 -> negativ | C14: =Base!$B$83 -> -0.0065111185 | D14: =Optimistisk!$B$83 -> 0.20329599
A15: NPV efter skat ved 8 % (EUR) | B15: =Pessimistisk!$B$84 -> -9919272.8 | C15: =Base!$B$84 -> -2629940.7 | D15: =Optimistisk!$B$84 -> 4038497.4
A16: Simpel tilbagebetalingstid (år) | B16: =Pessimistisk!$B$85 -> > levetid | C16: =Base!$B$85 -> > levetid | D16: =Optimistisk!$B$85 -> 5
A18: Hvad flytter base-scenariet? (én ændring ad gangen, IRR efter skat)
A19: Statiske tal beregnet 13.10.2026 med scripts/kontroller_model.py (samme logik som arkene). Opdateres ikke automatisk.
A20: Base som beregnet | B20: ca. -1 %
A21: Systemydelser holder dagens niveau (70k EUR/MW i stedet for 30k) | B21: ca. 6 %
A22: Investering 250 EUR/kWh i stedet for ca. 310 | B22: ca. 2 %
A23: Ingen betaling til RFV for netadgang | B23: ca. 1 %
A24: Intraday/ubalance-tillæg 20 % i stedet for 10 % | B24: ca. 1 %
A25: Levetid 20 år i stedet for 15 | B25: ca. 1 %
A26: 4 timer i stedet for 2 timer | B26: ca. -2 %
A27: Fuld elafgift 60,9 øre/kWh på opladning | B27: negativ (casen falder)
A28: Krav for 8 % efter skat: investering | B28: ca. 190 EUR/kWh
A29: Krav for 8 % efter skat: markedsindtægt | B29: ca. +43 %
A31: Sådan læses beregningen
A32: Indtjeningen bygger på en backtest af faktiske DK1-priser fra Energinet (okt. 2025 til okt. 2026), korrigeret for at et rigtigt batteri ikke kender priserne på forhånd. Systemydelser er sat lavere end i dag, fordi priserne allerede er faldet kraftigt, efterhånden som flere batterier er kommet på markedet. Se arket Backtest.
A33: Base-scenariet er bevidst konservativt. Resultatet er meget følsomt over for investering og markedsindtægt; se arket Følsomhed.
A35: Stop-risici (skal afklares før der bruges penge på udvikling)
A36: 1. Elafgift: modellen antager godtgørelse ned til 0,4 øre/kWh på opladning. Hvis den fulde afgift (60,9 øre/kWh fra 2028) rammer batteriet, falder business casen. Kræver bindende svar.
A37: 2. Netadgang: om netselskabet tillader et batteri (evt. ejet af et andet selskab end RFV) bag RFV's tilslutning, og om eksisterende kapacitet kan bruges uden nyt tilslutningsbidrag.
A38: 3. Samtidighed: elkedel og gasmotorer bruger tilslutningen i de samme timer, som batteriet vil bruge. Kræver RFV's 15-min. måledata og tilslutningsaftale.
A39: 4. Investering: base svarer til ca. 300 EUR/kWh all-in for 2h. Skal erstattes af 2-3 indikative tilbud.
A40: 5. Selskabsform: RFV er et forbrugerejet a.m.b.a. under varmeforsyningsloven. Deltagelse skal formentlig ske via et separat selskab. Skal verificeres juridisk.
A42: Bemærk: modellen regner ugearet projektafkast. Gæld hæver kun egenkapitalafkastet, hvis projektafkastet ligger over lånerenten.

Sheet Forudsætninger
A1: Forudsætninger: BESS ved Ringkøbing Fjernvarme (tidlig beregning, til godkendelse)
A2: Udarbejdet 13.10.2026. Gule celler er input og kan ændres; scenarie-arkene regner automatisk. Status: Data = fra kilde, Estimat = min vurdering, Skal verificeres / Ved ikke = skal afklares før beslutning.
A4: Nøgle | B4: Parameter | C4: Enhed | D4: Pessimistisk | E4: Base | F4: Optimistisk | G4: Status | H4: Kilde / begrundelse
A5: Projekt
A6: mw | B6: Batteriets effekt | C6: MW | D6: 10 | E6: 10 | F6: 10 | G6: Ved ikke | H6: Referencestørrelse. Den reelle størrelse afhænger af ledig import- og eksportkapacitet i RFV's tilslutning, som ikke er kendt.
A7: dur | B7: Varighed (1, 2 eller 4 timer) | C7: timer | D7: 2 | E7: 2 | F7: 2 | G7: Estimat | H7: Backtesten findes for 1, 2 og 4 timer (se arket Backtest). 4 timer giver mest indtjening pr. MW nettilslutning, men højere capex.
A8: cod | B8: Første driftsår (COD) | C8: år | D8: 2028 | E8: 2028 | F8: 2028 | G8: Estimat | H8: Antaget: udvikling, netaftale, indkøb og byggeri ca. 15-24 mdr. fra beslutning.
A9: life | B9: Økonomisk levetid | C9: år | D9: 15 | E9: 15 | F9: 15 | G9: Estimat | H9: Ingen restværdi og ingen udvidelse (augmentation) antaget. Maks. 20 år i modellen.
A10: avail | B10: Tilgængelighed inkl. konflikt med RFV's elkedel og gasmotorer | C10: % | D10: 0.85 | E10: 0.92 | F10: 0.97 | G10: Estimat | H10: Batteriet deler tilslutning med elkedel (import) og gasmotorer (eksport), der bruger kapaciteten i de samme timer. Skal afklares med RFV-data.
A11: fade | B11: Kapacitetstab pr. år (påvirker arbitrage) | C11: %/år | D11: 0.025 | E11: 0.02 | F11: 0.015 | G11: Estimat | H11: Typisk for LFP ved ca. 1 cyklus/døgn.
A12: rte | B12: Round-trip-virkningsgrad (AC-AC) | C12: % | D12: 0.86 | E12: 0.86 | F12: 0.86 | G12: Estimat | H12: Samme værdi som i backtesten.
A13: Anlægsomkostninger
A14: ckw | B14: Effektrelateret capex (PCS, trafo, HV/MV, BoP, EPC) | C14: EUR/kW | D14: 250 | E14: 200 | F14: 160 | G14: Estimat | H14: Kalibreret så 2h all-in ligger på 375/300/250 EUR/kWh. Ref.: Modo Energy (16.03.2026) 700k EUR/MW for 2h i Tyskland (scope ikke oplyst); BNEF Cost Survey 2025 Europa turnkey 177 USD/kWh ekskl. EPC og nettilslutning (via Energy-Storage.news, dec. 2025).
A15: ckwh | B15: Energirelateret capex (batteriblokke inkl. montage) | C15: EUR/kWh | D15: 250 | E15: 200 | F15: 170 | G15: Estimat | H15: Se ovenfor. Skal erstattes af tilbud.
A16: dev | B16: Udvikling, rådgivning, netstudier, finansiering | C16: EUR | D16: 400000 | E16: 250000 | F16: 150000 | G16: Estimat | H16: Juridisk, skat (bindende svar), netselskab, teknisk DD.
A17: conn | B17: Tilslutningsbidrag / ombygning af tilslutning | C17: EUR | D17: 300000 | E17: 0 | F17: 0 | G17: Skal verificeres | H17: Elnet.dk/Green Power Denmark: intet tilslutningsbidrag, hvis batteriet bruger eksisterende kapacitet uden at der søges ny. Pessimistisk: netselskabet kræver ombygning eller udvidelse.
A18: Indtægter (2026-priser)
A19: lvl | B19: Arbitrage-niveau ift. backtest seneste 12 mdr. | C19: faktor | D19: 0.836 | E19: 1 | F19: 1.126 | G19: Data | H19: Pess. = kalenderår 2025, Base = okt. 2025 til okt. 2026, Opt. = 2026 år-til-dato (annualiseret). 2h-backtest, se arket Backtest.
A20: cap | B20: Realiseringsgrad ift. perfekt forudsigelse (day-ahead) | C20: % | D20: 0.8 | E20: 0.85 | F20: 0.9 | G20: Estimat | H20: Backtesten antager perfekt kendskab til priserne.
A21: idu | B21: Tillæg fra intraday/ubalance | C21: % | D21: 0 | E21: 0.1 | F21: 0.2 | G21: Estimat | H21: Ikke backtestet. Kan være væsentligt i DK1, men usikkert.
A22: arbtr | B22: Real udvikling i arbitrage-indtjening | C22: %/år | D22: -0.03 | E22: -0.01 | F22: 0.01 | G22: Estimat | H22: Flere batterier presser spreads; mere sol og vind øger dem. Spreads i 2026 er høje sammen med et højt prisniveau.
A23: anc1 | B23: Systemydelser (aFRR + mFRR), netto merindtægt år 1 | C23: EUR/MW/år | D23: 15000 | E23: 30000 | F23: 70000 | G23: Data + estimat | H23: Backtest (2h, seneste 12 mdr.): merindtægt ift. ren arbitrage = 156k ved fulde priser, 70k ved 50 % og 30k ved 25 %. Priserne i Q3 2026 ligger på ca. 50 % af 12-mdr.-gennemsnittet. Base antager yderligere halvering frem til 2028.
A24: anctr | B24: Udvikling i systemydelser | C24: %/år | D24: -0.15 | E24: -0.05 | F24: -0.05 | G24: Estimat | H24: aFRR op i DK1 er faldet fra ca. 70 til ca. 6-10 EUR/MW/h (Q4 2024 til 2026).
A25: ancfl | B25: Gulv for systemydelser | C25: EUR/MW/år | D25: 0 | E25: 10000 | F25: 20000 | G25: Estimat
A26: Nettariffer og afgifter (betales af batteriet)
A27: t_en | B27: Energinet forbrugstarif (net + system) | C27: øre/kWh | D27: 12.5 | E27: 10.5 | F27: 10.5 | G27: Data | H27: Energinet-pressemeddelelse 04.09.2026: 10,5 øre/kWh i 2027 og loft på 12,5 øre/kWh frem til 2030.
A28: t_dso | B28: Netselskabets forbrugstarif (gns. i ladetimer) | C28: øre/kWh | D28: 5 | E28: 3 | F28: 2 | G28: Skal verificeres | H28: Netselskab og tarif for RFV's tilslutning er ikke kendt. Elnet.dk: batterier betaler både forbrugs- og indfødningstarif.
A29: t_afg | B29: Elafgift på opladning efter godtgørelse | C29: øre/kWh | D29: 0.4 | E29: 0.4 | F29: 0.4 | G29: Skal verificeres | H29: KRITISK. Lov nr. 1775 af 29.12.2025: 0,8 øre/kWh i 2026-27, derefter 60,9 øre (2015-niveau). Antaget: momsreg. virksomhed får godtgørelse ned til 0,4 øre. Gælder det ikke for et batteri fra 2028, falder business casen. Kræver bindende svar.
A30: t_enp | B30: Energinet indfødnings- og balancetarif | C30: øre/kWh | D30: 0.92 | E30: 0.92 | F30: 0.92 | G30: Data | H30: Energinet-pressemeddelelse 04.09.2026: 0,5 + 0,42 øre/kWh (2027).
A31: t_dsop | B31: Netselskabets indfødningstarif | C31: øre/kWh | D31: 0.5 | E31: 0.5 | F31: 0.5 | G31: Skal verificeres | H31: Estimat.
A32: fx | B32: Valutakurs | C32: DKK/EUR | D32: 7.46 | E32: 7.46 | F32: 7.46 | G32: Data | H32: Fast kurs (ERM2).
A33: Driftsomkostninger (2026-priser)
A34: om | B34: Drift og vedligehold (LTSA) | C34: % af anlægscapex | D34: 0.02 | E34: 0.015 | F34: 0.012 | G34: Estimat
A35: ins | B35: Forsikring | C35: % af anlægscapex | D35: 0.005 | E35: 0.004 | F35: 0.003 | G35: Estimat
A36: fee | B36: Optimerings-/aggregatorfee | C36: % af markedsindtægt | D36: 0.15 | E36: 0.1 | F36: 0.07 | G36: Estimat | H36: Alternativ: fast fee pr. MW eller gevinstdeling.
A37: rfv | B37: Betaling til RFV for netadgang og areal | C37: EUR/MW/år | D37: 10000 | E37: 6000 | F37: 3000 | G37: Ved ikke | H37: Til forhandling. Kan også erstattes af ejerandel til RFV.
A38: fix | B38: Faste omkostninger (adm., revision, BRP, SCADA, abonnementer) | C38: EUR/år | D38: 60000 | E38: 40000 | F38: 30000 | G38: Estimat
A39: Økonomi og skat
A40: infl | B40: Inflation (indeksering fra 2026-niveau) | C40: %/år | D40: 0.02 | E40: 0.02 | F40: 0.02 | G40: Estimat
A41: tax | B41: Selskabsskat | C41: % | D41: 0.22 | E41: 0.22 | F41: 0.22 | G41: Data | H41: Dansk selskabsskat.
...

Sheet Backtest
A1: Backtest af batteri i DK1 på Energinet-data (perfekt forudsigelse)
A2: Beregnet 13.10.2026 med scripts/backtest_dk1.py på data fra Energinets Energi Data Service (Elspotprices, DayAheadPrices, AfrrReservesNordic, FcrDK1, mFRRCapacityMarket).
A3: Metode: lineær optimering pr. døgn for 1 MW. Round-trip 86 %, maks. 1,5 cyklus/døgn, SoC 50 % ved døgnstart og -slut. Reserver kræver energi til 60 min (aFRR/mFRR) og 30 min (FCR).
A4: Netomkostning i optimeringen: 18,6 EUR/MWh på opladning og 1,9 EUR/MWh på afladning (svarer til base-tarifferne). Kvartersopløsning fra 1.10.2025, timeopløsning før.
A5: Perfekt forudsigelse overvurderer indtjeningen; det korrigeres med realiseringsgraden i Forudsætninger. Ubegrænset reservevolumen er urealistisk i DK1 (lille marked), se mætningsvarianter.
A7: A. Indtjening pr. MW pr. år, 2h-batteri (EUR, annualiseret)
A8: Periode | B8: Strategi | C8: Arbitrage brutto | D8: Netomkostning | E8: aFRR | F8: FCR | G8: mFRR | H8: Netto | I8: MWh afladet | J8: Dage
A9: Kalenderår 2024 | B9: Kun day-ahead-arbitrage | C9: 55896.431 | D9: -16988.641 | E9: 0 | F9: 0 | G9: 0 | H9: 38907.79 | I9: 722.06342 | J9: 366
A10: Kalenderår 2024 | B10: Day-ahead + alle reserver (ubegrænset volumen) | C10: 18790.452 | D10: -4376.3314 | E10: 176256.11 | F10: 106904.27 | G10: 35416.372 | H10: 332990.87 | I10: 186.00598 | J10: 366
A11: Kalenderår 2025 | B11: Kun day-ahead-arbitrage | C11: 69181.439 | D11: -18189.468 | E11: 0 | F11: 0 | G11: 0 | H11: 50991.971 | I11: 773.10185 | J11: 365
A12: Kalenderår 2025 | B12: Day-ahead + alle reserver (ubegrænset volumen) | C12: 17592.163 | D12: -3897.1289 | E12: 268953.5 | F12: 60227.864 | G12: 57669.762 | H12: 400546.16 | I12: 165.63857 | J12: 365
A13: 13.10.2025 til 12.10.2026 | B13: Kun day-ahead-arbitrage | C13: 82753.375 | D13: -18323.839 | E13: 0 | F13: 0 | G13: 0 | H13: 64429.536 | I13: 778.81296 | J13: 365
A14: 13.10.2025 til 12.10.2026 | B14: Day-ahead + alle reserver (ubegrænset volumen) | C14: 30214.333 | D14: -5765.2906 | E14: 85907.587 | F14: 99818.091 | G14: 76572.664 | H14: 286747.38 | I14: 245.04052 | J14: 365
A15: 2026 år-til-dato | B15: Kun day-ahead-arbitrage | C15: 93165.726 | D15: -19266.565 | E15: 0 | F15: 0 | G15: 0 | H15: 73899.16 | I15: 818.8814 | J15: 285
A16: 2026 år-til-dato | B16: Day-ahead + alle reserver (ubegrænset volumen) | C16: 36245.029 | D16: -6661.6658 | E16: 63004.575 | F16: 119102.9 | G16: 78613.162 | H16: 290304 | I16: 283.13891 | J16: 285
A18: B. Varighed, kun day-ahead, seneste 12 mdr. (bruges af modellen)
A19: Varighed (timer) | B19: Kilde | C19: Arbitrage brutto EUR/MW/år | D19: MWh afladet pr. MW/år | E19: Netto EUR/MW/år
A20: 1 | B20: backtest_varianter.py | C20: 46403 | D20: 425 | E20: 36404
A21: 2 | B21: backtest_dk1.py | C21: 82753.375 | D21: 778.81296 | E21: 64429.536
A22: 4 | B22: backtest_varianter.py | C22: 135158 | D22: 1302 | E22: 104536
A24: C. Mætning af systemydelser: 2h, seneste 12 mdr., aFRR + mFRR (uden FCR), reservepriser skaleret
A25: Reservepris-faktor | B25: Arbitrage brutto | C25: Netomkostning | D25: aFRR | E25: mFRR | F25: Netto | G25: Merindtægt ift. ren arbitrage
A26: 1 | B26: 54252 | C26: -11364 | D26: 95069 | E26: 82536 | F26: 220493 | G26: 156063.46
A27: 0.5 | B27: 64544 | C27: -13162 | D27: 44689 | E27: 37960 | F27: 134031 | G27: 69601.464
A28: 0.25 | B28: 72429 | C28: -14877 | D28: 20003 | E28: 16979 | F28: 94534 | G28: 30104.464
A30: D. DK1 pr. kvartal: prisspænd og reservepriser (gennemsnit). Q4 2026 er kun 1.-13. oktober.
A31: Kvartal | B31: Dagligt spænd top-2h minus bund-2h (EUR/MWh) | C31: Gns. spotpris (EUR/MWh) | D31: aFRR op (EUR/MW/h) | E31: aFRR ned (EUR/MW/h) | F31: FCR DK1 (EUR/MW/h) | G31: mFRR op (EUR/MW/h) | H31: aFRR op behov (MW) | I31: aFRR ned behov (MW) | J31: FCR fra danske enheder (MW) | K31: mFRR op behov (MW)
A32: 2023Q1 | B32: 76.9 | C32: 109.6 | F32: 16.4 | J32: 1.2
A33: 2023Q2 | B33: 86.7 | C33: 87.4 | F33: 9.8 | G33: 0.6 | J33: 0.8
A34: 2023Q3 | B34: 109.8 | C34: 78.4 | F34: 9.7 | G34: 7.4 | J34: 1.8
A35: 2023Q4 | B35: 74 | C35: 72.4 | F35: 15.3 | G35: 1.6 | J35: 3.8
A36: 2024Q1 | B36: 47.7 | C36: 65 | F36: 9.2 | G36: 4.4 | J36: 2.9 | K36: 284
A37: 2024Q2 | B37: 95 | C37: 60.5 | F37: 21.8 | G37: 0.7 | J37: 3.8 | K37: 289.4
A38: 2024Q3 | B38: 122.5 | C38: 68.9 | F38: 21.1 | G38: 12 | J38: 3 | K38: 313.1
A39: 2024Q4 | B39: 105.2 | C39: 88.1 | D39: 70.3 | E39: 13.3 | F39: 12.9 | G39: 6.1 | J39: 2 | K39: 302.8
A40: 2025Q1 | B40: 99.8 | C40: 97.9 | D40: 41.6 | E40: 1.3 | F40: 10.9 | G40: 15 | J40: 2.8 | K40: 317
A41: 2025Q2 | B41: 129.4 | C41: 66 | D41: 46.3 | E41: 1.1 | F41: 22.4 | G41: 4.5 | J41: 8.8 | K41: 292.3
A42: 2025Q3 | B42: 123.6 | C42: 76.3 | D42: 35.3 | E42: 0.5 | F42: 16.9 | G42: 12.3 | H42: 99.8 | I42: 99.8 | J42: 10.4 | K42: 262.7
A43: 2025Q4 | B43: 75.7 | C43: 84.5 | D43: 21.8 | E43: 0.3 | F43: 10.5 | G43: 13.4 | H43: 100 | I43: 100 | J43: 7.7 | K43: 351.1
A44: 2026Q1 | B44: 84.8 | C44: 99.9 | D44: 15.3 | E44: 0.6 | F44: 11.8 | G44: 17.9 | H44: 95.4 | I44: 68.9 | J44: 3.8 | K44: 322.1
...

Sheet Pessimistisk
A1: Cash flow: Pessimistisk scenarie (EUR, nominelt)
A2: Scenarie-indeks (1 = pess., 2 = base, 3 = opt.) | B2: 1
A4: Forudsætninger for scenariet (hentes fra arket Forudsætninger)
A5: Batteriets effekt [MW] | B5: =INDEX(Forudsætninger!$D$6:$F$6,1,$B$2) -> 10
A6: Varighed (1, 2 eller 4 timer) [timer] | B6: =INDEX(Forudsætninger!$D$7:$F$7,1,$B$2) -> 2
A7: Første driftsår (COD) [år] | B7: =INDEX(Forudsætninger!$D$8:$F$8,1,$B$2) -> 2028
A8: Økonomisk levetid [år] | B8: =INDEX(Forudsætninger!$D$9:$F$9,1,$B$2) -> 15
A9: Tilgængelighed inkl. konflikt med RFV's elkedel og gasmotorer [%] | B9: =INDEX(Forudsætninger!$D$10:$F$10,1,$B$2) -> 0.85
A10: Kapacitetstab pr. år (påvirker arbitrage) [%/år] | B10: =INDEX(Forudsætninger!$D$11:$F$11,1,$B$2) -> 0.025
A11: Round-trip-virkningsgrad (AC-AC) [%] | B11: =INDEX(Forudsætninger!$D$12:$F$12,1,$B$2) -> 0.86
A12: Effektrelateret capex (PCS, trafo, HV/MV, BoP, EPC) [EUR/kW] | B12: =INDEX(Forudsætninger!$D$14:$F$14,1,$B$2) -> 250
A13: Energirelateret capex (batteriblokke inkl. montage) [EUR/kWh] | B13: =INDEX(Forudsætninger!$D$15:$F$15,1,$B$2) -> 250
A14: Udvikling, rådgivning, netstudier, finansiering [EUR] | B14: =INDEX(Forudsætninger!$D$16:$F$16,1,$B$2) -> 400000
A15: Tilslutningsbidrag / ombygning af tilslutning [EUR] | B15: =INDEX(Forudsætninger!$D$17:$F$17,1,$B$2) -> 300000
A16: Arbitrage-niveau ift. backtest seneste 12 mdr. [faktor] | B16: =INDEX(Forudsætninger!$D$19:$F$19,1,$B$2) -> 0.836
A17: Realiseringsgrad ift. perfekt forudsigelse (day-ahead) [%] | B17: =INDEX(Forudsætninger!$D$20:$F$20,1,$B$2) -> 0.8
A18: Tillæg fra intraday/ubalance [%] | B18: =INDEX(Forudsætninger!$D$21:$F$21,1,$B$2) -> 0
A19: Real udvikling i arbitrage-indtjening [%/år] | B19: =INDEX(Forudsætninger!$D$22:$F$22,1,$B$2) -> -0.03
A20: Systemydelser (aFRR + mFRR), netto merindtægt år 1 [EUR/MW/år] | B20: =INDEX(Forudsætninger!$D$23:$F$23,1,$B$2) -> 15000
A21: Udvikling i systemydelser [%/år] | B21: =INDEX(Forudsætninger!$D$24:$F$24,1,$B$2) -> -0.15
A22: Gulv for systemydelser [EUR/MW/år] | B22: =INDEX(Forudsætninger!$D$25:$F$25,1,$B$2) -> 0
A23: Energinet forbrugstarif (net + system) [øre/kWh] | B23: =INDEX(Forudsætninger!$D$27:$F$27,1,$B$2) -> 12.5
A24: Netselskabets forbrugstarif (gns. i ladetimer) [øre/kWh] | B24: =INDEX(Forudsætninger!$D$28:$F$28,1,$B$2) -> 5
A25: Elafgift på opladning efter godtgørelse [øre/kWh] | B25: =INDEX(Forudsætninger!$D$29:$F$29,1,$B$2) -> 0.4
A26: Energinet indfødnings- og balancetarif [øre/kWh] | B26: =INDEX(Forudsætninger!$D$30:$F$30,1,$B$2) -> 0.92
A27: Netselskabets indfødningstarif [øre/kWh] | B27: =INDEX(Forudsætninger!$D$31:$F$31,1,$B$2) -> 0.5
A28: Valutakurs [DKK/EUR] | B28: =INDEX(Forudsætninger!$D$32:$F$32,1,$B$2) -> 7.46
A29: Drift og vedligehold (LTSA) [% af anlægscapex] | B29: =INDEX(Forudsætninger!$D$34:$F$34,1,$B$2) -> 0.02
A30: Forsikring [% af anlægscapex] | B30: =INDEX(Forudsætninger!$D$35:$F$35,1,$B$2) -> 0.005
A31: Optimerings-/aggregatorfee [% af markedsindtægt] | B31: =INDEX(Forudsætninger!$D$36:$F$36,1,$B$2) -> 0.15
A32: Betaling til RFV for netadgang og areal [EUR/MW/år] | B32: =INDEX(Forudsætninger!$D$37:$F$37,1,$B$2) -> 10000
A33: Faste omkostninger (adm., revision, BRP, SCADA, abonnementer) [EUR/år] | B33: =INDEX(Forudsætninger!$D$38:$F$38,1,$B$2) -> 60000
A34: Inflation (indeksering fra 2026-niveau) [%/år] | B34: =INDEX(Forudsætninger!$D$40:$F$40,1,$B$2) -> 0.02
A35: Selskabsskat [%] | B35: =INDEX(Forudsætninger!$D$41:$F$41,1,$B$2) -> 0.22
A36: Skattemæssig afskrivning (saldo) [%/år] | B36: =INDEX(Forudsætninger!$D$42:$F$42,1,$B$2) -> 0.25
A37: Diskonteringsrente til NPV (nominel) [%] | B37: =INDEX(Forudsætninger!$D$43:$F$43,1,$B$2) -> 0.08
A39: Afledte størrelser
A40: Energi (MWh) | B40: =$B$5*$B$6 -> 20
A41: Anlægscapex (effekt + energi) | B41: =$B$5*1000*$B$12+$B$5*$B$6*1000*$B$13 -> 7500000
A42: Samlet investering | B42: =B41+$B$14+$B$15 -> 8200000
...

Sheet Base
A1: Cash flow: Base scenarie (EUR, nominelt)
A2: Scenarie-indeks (1 = pess., 2 = base, 3 = opt.) | B2: 2
A4: Forudsætninger for scenariet (hentes fra arket Forudsætninger)
A5: Batteriets effekt [MW] | B5: =INDEX(Forudsætninger!$D$6:$F$6,1,$B$2) -> 10
A6: Varighed (1, 2 eller 4 timer) [timer] | B6: =INDEX(Forudsætninger!$D$7:$F$7,1,$B$2) -> 2
A7: Første driftsår (COD) [år] | B7: =INDEX(Forudsætninger!$D$8:$F$8,1,$B$2) -> 2028
A8: Økonomisk levetid [år] | B8: =INDEX(Forudsætninger!$D$9:$F$9,1,$B$2) -> 15
A9: Tilgængelighed inkl. konflikt med RFV's elkedel og gasmotorer [%] | B9: =INDEX(Forudsætninger!$D$10:$F$10,1,$B$2) -> 0.92
A10: Kapacitetstab pr. år (påvirker arbitrage) [%/år] | B10: =INDEX(Forudsætninger!$D$11:$F$11,1,$B$2) -> 0.02
A11: Round-trip-virkningsgrad (AC-AC) [%] | B11: =INDEX(Forudsætninger!$D$12:$F$12,1,$B$2) -> 0.86
A12: Effektrelateret capex (PCS, trafo, HV/MV, BoP, EPC) [EUR/kW] | B12: =INDEX(Forudsætninger!$D$14:$F$14,1,$B$2) -> 200
A13: Energirelateret capex (batteriblokke inkl. montage) [EUR/kWh] | B13: =INDEX(Forudsætninger!$D$15:$F$15,1,$B$2) -> 200
A14: Udvikling, rådgivning, netstudier, finansiering [EUR] | B14: =INDEX(Forudsætninger!$D$16:$F$16,1,$B$2) -> 250000
A15: Tilslutningsbidrag / ombygning af tilslutning [EUR] | B15: =INDEX(Forudsætninger!$D$17:$F$17,1,$B$2) -> 0
A16: Arbitrage-niveau ift. backtest seneste 12 mdr. [faktor] | B16: =INDEX(Forudsætninger!$D$19:$F$19,1,$B$2) -> 1
A17: Realiseringsgrad ift. perfekt forudsigelse (day-ahead) [%] | B17: =INDEX(Forudsætninger!$D$20:$F$20,1,$B$2) -> 0.85
A18: Tillæg fra intraday/ubalance [%] | B18: =INDEX(Forudsætninger!$D$21:$F$21,1,$B$2) -> 0.1
A19: Real udvikling i arbitrage-indtjening [%/år] | B19: =INDEX(Forudsætninger!$D$22:$F$22,1,$B$2) -> -0.01
A20: Systemydelser (aFRR + mFRR), netto merindtægt år 1 [EUR/MW/år] | B20: =INDEX(Forudsætninger!$D$23:$F$23,1,$B$2) -> 30000
A21: Udvikling i systemydelser [%/år] | B21: =INDEX(Forudsætninger!$D$24:$F$24,1,$B$2) -> -0.05
A22: Gulv for systemydelser [EUR/MW/år] | B22: =INDEX(Forudsætninger!$D$25:$F$25,1,$B$2) -> 10000
A23: Energinet forbrugstarif (net + system) [øre/kWh] | B23: =INDEX(Forudsætninger!$D$27:$F$27,1,$B$2) -> 10.5
A24: Netselskabets forbrugstarif (gns. i ladetimer) [øre/kWh] | B24: =INDEX(Forudsætninger!$D$28:$F$28,1,$B$2) -> 3
A25: Elafgift på opladning efter godtgørelse [øre/kWh] | B25: =INDEX(Forudsætninger!$D$29:$F$29,1,$B$2) -> 0.4
A26: Energinet indfødnings- og balancetarif [øre/kWh] | B26: =INDEX(Forudsætninger!$D$30:$F$30,1,$B$2) -> 0.92
A27: Netselskabets indfødningstarif [øre/kWh] | B27: =INDEX(Forudsætninger!$D$31:$F$31,1,$B$2) -> 0.5
A28: Valutakurs [DKK/EUR] | B28: =INDEX(Forudsætninger!$D$32:$F$32,1,$B$2) -> 7.46
A29: Drift og vedligehold (LTSA) [% af anlægscapex] | B29: =INDEX(Forudsætninger!$D$34:$F$34,1,$B$2) -> 0.015
A30: Forsikring [% af anlægscapex] | B30: =INDEX(Forudsætninger!$D$35:$F$35,1,$B$2) -> 0.004
A31: Optimerings-/aggregatorfee [% af markedsindtægt] | B31: =INDEX(Forudsætninger!$D$36:$F$36,1,$B$2) -> 0.1
A32: Betaling til RFV for netadgang og areal [EUR/MW/år] | B32: =INDEX(Forudsætninger!$D$37:$F$37,1,$B$2) -> 6000
A33: Faste omkostninger (adm., revision, BRP, SCADA, abonnementer) [EUR/år] | B33: =INDEX(Forudsætninger!$D$38:$F$38,1,$B$2) -> 40000
A34: Inflation (indeksering fra 2026-niveau) [%/år] | B34: =INDEX(Forudsætninger!$D$40:$F$40,1,$B$2) -> 0.02
A35: Selskabsskat [%] | B35: =INDEX(Forudsætninger!$D$41:$F$41,1,$B$2) -> 0.22
A36: Skattemæssig afskrivning (saldo) [%/år] | B36: =INDEX(Forudsætninger!$D$42:$F$42,1,$B$2) -> 0.25
A37: Diskonteringsrente til NPV (nominel) [%] | B37: =INDEX(Forudsætninger!$D$43:$F$43,1,$B$2) -> 0.08
A39: Afledte størrelser
A40: Energi (MWh) | B40: =$B$5*$B$6 -> 20
A41: Anlægscapex (effekt + energi) | B41: =$B$5*1000*$B$12+$B$5*$B$6*1000*$B$13 -> 6000000
A42: Samlet investering | B42: =B41+$B$14+$B$15 -> 6250000
...

Sheet Optimistisk
A1: Cash flow: Optimistisk scenarie (EUR, nominelt)
A2: Scenarie-indeks (1 = pess., 2 = base, 3 = opt.) | B2: 3
A4: Forudsætninger for scenariet (hentes fra arket Forudsætninger)
A5: Batteriets effekt [MW] | B5: =INDEX(Forudsætninger!$D$6:$F$6,1,$B$2) -> 10
A6: Varighed (1, 2 eller 4 timer) [timer] | B6: =INDEX(Forudsætninger!$D$7:$F$7,1,$B$2) -> 2
A7: Første driftsår (COD) [år] | B7: =INDEX(Forudsætninger!$D$8:$F$8,1,$B$2) -> 2028
A8: Økonomisk levetid [år] | B8: =INDEX(Forudsætninger!$D$9:$F$9,1,$B$2) -> 15
A9: Tilgængelighed inkl. konflikt med RFV's elkedel og gasmotorer [%] | B9: =INDEX(Forudsætninger!$D$10:$F$10,1,$B$2) -> 0.97
A10: Kapacitetstab pr. år (påvirker arbitrage) [%/år] | B10: =INDEX(Forudsætninger!$D$11:$F$11,1,$B$2) -> 0.015
A11: Round-trip-virkningsgrad (AC-AC) [%] | B11: =INDEX(Forudsætninger!$D$12:$F$12,1,$B$2) -> 0.86
A12: Effektrelateret capex (PCS, trafo, HV/MV, BoP, EPC) [EUR/kW] | B12: =INDEX(Forudsætninger!$D$14:$F$14,1,$B$2) -> 160
A13: Energirelateret capex (batteriblokke inkl. montage) [EUR/kWh] | B13: =INDEX(Forudsætninger!$D$15:$F$15,1,$B$2) -> 170
A14: Udvikling, rådgivning, netstudier, finansiering [EUR] | B14: =INDEX(Forudsætninger!$D$16:$F$16,1,$B$2) -> 150000
A15: Tilslutningsbidrag / ombygning af tilslutning [EUR] | B15: =INDEX(Forudsætninger!$D$17:$F$17,1,$B$2) -> 0
A16: Arbitrage-niveau ift. backtest seneste 12 mdr. [faktor] | B16: =INDEX(Forudsætninger!$D$19:$F$19,1,$B$2) -> 1.126
A17: Realiseringsgrad ift. perfekt forudsigelse (day-ahead) [%] | B17: =INDEX(Forudsætninger!$D$20:$F$20,1,$B$2) -> 0.9
A18: Tillæg fra intraday/ubalance [%] | B18: =INDEX(Forudsætninger!$D$21:$F$21,1,$B$2) -> 0.2
A19: Real udvikling i arbitrage-indtjening [%/år] | B19: =INDEX(Forudsætninger!$D$22:$F$22,1,$B$2) -> 0.01
A20: Systemydelser (aFRR + mFRR), netto merindtægt år 1 [EUR/MW/år] | B20: =INDEX(Forudsætninger!$D$23:$F$23,1,$B$2) -> 70000
A21: Udvikling i systemydelser [%/år] | B21: =INDEX(Forudsætninger!$D$24:$F$24,1,$B$2) -> -0.05
A22: Gulv for systemydelser [EUR/MW/år] | B22: =INDEX(Forudsætninger!$D$25:$F$25,1,$B$2) -> 20000
A23: Energinet forbrugstarif (net + system) [øre/kWh] | B23: =INDEX(Forudsætninger!$D$27:$F$27,1,$B$2) -> 10.5
A24: Netselskabets forbrugstarif (gns. i ladetimer) [øre/kWh] | B24: =INDEX(Forudsætninger!$D$28:$F$28,1,$B$2) -> 2
A25: Elafgift på opladning efter godtgørelse [øre/kWh] | B25: =INDEX(Forudsætninger!$D$29:$F$29,1,$B$2) -> 0.4
A26: Energinet indfødnings- og balancetarif [øre/kWh] | B26: =INDEX(Forudsætninger!$D$30:$F$30,1,$B$2) -> 0.92
A27: Netselskabets indfødningstarif [øre/kWh] | B27: =INDEX(Forudsætninger!$D$31:$F$31,1,$B$2) -> 0.5
A28: Valutakurs [DKK/EUR] | B28: =INDEX(Forudsætninger!$D$32:$F$32,1,$B$2) -> 7.46
A29: Drift og vedligehold (LTSA) [% af anlægscapex] | B29: =INDEX(Forudsætninger!$D$34:$F$34,1,$B$2) -> 0.012
A30: Forsikring [% af anlægscapex] | B30: =INDEX(Forudsætninger!$D$35:$F$35,1,$B$2) -> 0.003
A31: Optimerings-/aggregatorfee [% af markedsindtægt] | B31: =INDEX(Forudsætninger!$D$36:$F$36,1,$B$2) -> 0.07
A32: Betaling til RFV for netadgang og areal [EUR/MW/år] | B32: =INDEX(Forudsætninger!$D$37:$F$37,1,$B$2) -> 3000
A33: Faste omkostninger (adm., revision, BRP, SCADA, abonnementer) [EUR/år] | B33: =INDEX(Forudsætninger!$D$38:$F$38,1,$B$2) -> 30000
A34: Inflation (indeksering fra 2026-niveau) [%/år] | B34: =INDEX(Forudsætninger!$D$40:$F$40,1,$B$2) -> 0.02
A35: Selskabsskat [%] | B35: =INDEX(Forudsætninger!$D$41:$F$41,1,$B$2) -> 0.22
A36: Skattemæssig afskrivning (saldo) [%/år] | B36: =INDEX(Forudsætninger!$D$42:$F$42,1,$B$2) -> 0.25
A37: Diskonteringsrente til NPV (nominel) [%] | B37: =INDEX(Forudsætninger!$D$43:$F$43,1,$B$2) -> 0.08
A39: Afledte størrelser
A40: Energi (MWh) | B40: =$B$5*$B$6 -> 20
A41: Anlægscapex (effekt + energi) | B41: =$B$5*1000*$B$12+$B$5*$B$6*1000*$B$13 -> 5000000
A42: Samlet investering | B42: =B41+$B$14+$B$15 -> 5150000
...

Sheet Følsomhed
A1: Følsomhed: IRR før skat i base-scenariet ved ændret investering og markedsindtægt
A2: Markedsindtægt skaleres (arbitrage + systemydelser); nettariffer følger volumen og skaleres ikke. Drift og forsikring følger investeringen. Ændr faktorerne i de gule celler.
A4: Markedsindtægt (faktor) ned / investering (faktor) hen | B4: 0.6 | C4: 0.8 | D4: 0.9 | E4: 1 | F4: 1.1 | G4: 1.2
A5: 0.7 | B5: =IFERROR(IRR(B14:V14),"negativ") -> -0.028822658 | C5: =IFERROR(IRR(B15:V15),"negativ") -> -0.083620099 | D5: =IFERROR(IRR(B16:V16),"negativ") -> -0.10737553 | E5: =IFERROR(IRR(B17:V17),"negativ") -> negativ | F5: =IFERROR(IRR(B18:V18),"negativ") -> negativ | G5: =IFERROR(IRR(B19:V19),"negativ") -> negativ
A6: 0.85 | B6: =IFERROR(IRR(B20:V20),"negativ") -> 0.040689133 | C6: =IFERROR(IRR(B21:V21),"negativ") -> -0.014401728 | D6: =IFERROR(IRR(B22:V22),"negativ") -> -0.036089053 | E6: =IFERROR(IRR(B23:V23),"negativ") -> -0.055428956 | F6: =IFERROR(IRR(B24:V24),"negativ") -> -0.073105692 | G6: =IFERROR(IRR(B25:V25),"negativ") -> -0.089613227
A7: 1 | B7: =IFERROR(IRR(B26:V26),"negativ") -> 0.095455337 | C7: =IFERROR(IRR(B27:V27),"negativ") -> 0.035692246 | D7: =IFERROR(IRR(B28:V28),"negativ") -> 0.013097621 | E7: =IFERROR(IRR(B29:V29),"negativ") -> -0.0065111185 | F7: =IFERROR(IRR(B30:V30),"negativ") -> -0.02392159 | G7: =IFERROR(IRR(B31:V31),"negativ") -> -0.039673975
A8: 1.15 | B8: =IFERROR(IRR(B32:V32),"negativ") -> 0.14352006 | C8: =IFERROR(IRR(B33:V33),"negativ") -> 0.077698472 | D8: =IFERROR(IRR(B34:V34),"negativ") -> 0.053440653 | E8: =IFERROR(IRR(B35:V35),"negativ") -> 0.032719424 | F8: =IFERROR(IRR(B36:V36),"negativ") -> 0.01461031 | G8: =IFERROR(IRR(B37:V37),"negativ") -> -0.0015119058
A9: 1.3 | B9: =IFERROR(IRR(B38:V38),"negativ") -> 0.18787181 | C9: =IFERROR(IRR(B39:V39),"negativ") -> 0.11526374 | D9: =IFERROR(IRR(B40:V40),"negativ") -> 0.089001224 | E9: =IFERROR(IRR(B41:V41),"negativ") -> 0.066817838 | F9: =IFERROR(IRR(B42:V42),"negativ") -> 0.047640347 | G9: =IFERROR(IRR(B43:V43),"negativ") -> 0.030748294
A10: 1.5 | B10: =IFERROR(IRR(B44:V44),"negativ") -> 0.24362723 | C10: =IFERROR(IRR(B45:V45),"negativ") -> 0.1612362 | D10: =IFERROR(IRR(B46:V46),"negativ") -> 0.13199252 | E10: =IFERROR(IRR(B47:V47),"negativ") -> 0.10756616 | F10: =IFERROR(IRR(B48:V48),"negativ") -> 0.086673876 | G10: =IFERROR(IRR(B49:V49),"negativ") -> 0.06845956
A13: Hjælpeberegning (cash flow før skat pr. kombination)
A14: ="Indtægt "&TEXT($A$5,"0%")&" / investering "&TEXT(B$4,"0%") -> Indtægt 70% / investering 60% | B14: =Base!C65*B$4 -> -3750000 | C14: =$A$5*Base!D58*(1-Base!$B$31)+Base!D59+B$4*Base!D60+Base!D62+Base!D63 -> 296581.9 | D14: =$A$5*Base!E58*(1-Base!$B$31)+Base!E59+B$4*Base!E60+Base!E62+Base!E63 -> 282689.5 | E14: =$A$5*Base!F58*(1-Base!$B$31)+Base!F59+B$4*Base!F60+Base!F62+Base!F63 -> 268951.26 | F14: =$A$5*Base!G58*(1-Base!$B$31)+Base!G59+B$4*Base!G60+Base!G62+Base!G63 -> 255359.88 | G14: =$A$5*Base!H58*(1-Base!$B$31)+Base!H59+B$4*Base!H60+Base!H62+Base!H63 -> 241908.18 | H14: =$A$5*Base!I58*(1-Base!$B$31)+Base!I59+B$4*Base!I60+Base!I62+Base!I63 -> 228589.13 | I14: =$A$5*Base!J58*(1-Base!$B$31)+Base!J59+B$4*Base!J60+Base!J62+Base!J63 -> 215395.82 | J14: =$A$5*Base!K58*(1-Base!$B$31)+Base!K59+B$4*Base!K60+Base!K62+Base!K63 -> 202321.5 | K14: =$A$5*Base!L58*(1-Base!$B$31)+Base!L59+B$4*Base!L60+Base!L62+Base!L63 -> 189359.5 | L14: =$A$5*Base!M58*(1-Base!$B$31)+Base!M59+B$4*Base!M60+Base!M62+Base!M63 -> 176503.3 | M14: =$A$5*Base!N58*(1-Base!$B$31)+Base!N59+B$4*Base!N60+Base!N62+Base!N63 -> 163746.48 | N14: =$A$5*Base!O58*(1-Base!$B$31)+Base!O59+B$4*Base!O60+Base!O62+Base!O63 -> 151082.72 | O14: =$A$5*Base!P58*(1-Base!$B$31)+Base!P59+B$4*Base!P60+Base!P62+Base!P63 -> 138505.81 | P14: =$A$5*Base!Q58*(1-Base!$B$31)+Base!Q59+B$4*Base!Q60+Base!Q62+Base!Q63 -> 126009.64 | Q14: =$A$5*Base!R58*(1-Base!$B$31)+Base!R59+B$4*Base!R60+Base!R62+Base!R63 -> 113588.18 | R14: =$A$5*Base!S58*(1-Base!$B$31)+Base!S59+B$4*Base!S60+Base!S62+Base!S63 -> 0 | S14: =$A$5*Base!T58*(1-Base!$B$31)+Base!T59+B$4*Base!T60+Base!T62+Base!T63 -> 0 | T14: =$A$5*Base!U58*(1-Base!$B$31)+Base!U59+B$4*Base!U60+Base!U62+Base!U63 -> 0 | U14: =$A$5*Base!V58*(1-Base!$B$31)+Base!V59+B$4*Base!V60+Base!V62+Base!V63 -> 0 | V14: =$A$5*Base!W58*(1-Base!$B$31)+Base!W59+B$4*Base!W60+Base!W62+Base!W63 -> 0
A15: ="Indtægt "&TEXT($A$5,"0%")&" / investering "&TEXT(C$4,"0%") -> Indtægt 70% / investering 80% | B15: =Base!C65*C$4 -> -5000000 | C15: =$A$5*Base!D58*(1-Base!$B$31)+Base!D59+C$4*Base!D60+Base!D62+Base!D63 -> 272860.78 | D15: =$A$5*Base!E58*(1-Base!$B$31)+Base!E59+C$4*Base!E60+Base!E62+Base!E63 -> 258493.95 | E15: =$A$5*Base!F58*(1-Base!$B$31)+Base!F59+C$4*Base!F60+Base!F62+Base!F63 -> 244271.81 | F15: =$A$5*Base!G58*(1-Base!$B$31)+Base!G59+C$4*Base!G60+Base!G62+Base!G63 -> 230186.84 | G15: =$A$5*Base!H58*(1-Base!$B$31)+Base!H59+C$4*Base!H60+Base!H62+Base!H63 -> 216231.68 | H15: =$A$5*Base!I58*(1-Base!$B$31)+Base!I59+C$4*Base!I60+Base!I62+Base!I63 -> 202399.09 | I15: =$A$5*Base!J58*(1-Base!$B$31)+Base!J59+C$4*Base!J60+Base!J62+Base!J63 -> 188681.99 | J15: =$A$5*Base!K58*(1-Base!$B$31)+Base!K59+C$4*Base!K60+Base!K62+Base!K63 -> 175073.39 | K15: =$A$5*Base!L58*(1-Base!$B$31)+Base!L59+C$4*Base!L60+Base!L62+Base!L63 -> 161566.43 | L15: =$A$5*Base!M58*(1-Base!$B$31)+Base!M59+C$4*Base!M60+Base!M62+Base!M63 -> 148154.37 | M15: =$A$5*Base!N58*(1-Base!$B$31)+Base!N59+C$4*Base!N60+Base!N62+Base!N63 -> 134830.57 | N15: =$A$5*Base!O58*(1-Base!$B$31)+Base!O59+C$4*Base!O60+Base!O62+Base!O63 -> 121588.49 | O15: =$A$5*Base!P58*(1-Base!$B$31)+Base!P59+C$4*Base!P60+Base!P62+Base!P63 -> 108421.7 | P15: =$A$5*Base!Q58*(1-Base!$B$31)+Base!Q59+C$4*Base!Q60+Base!Q62+Base!Q63 -> 95323.843 | Q15: =$A$5*Base!R58*(1-Base!$B$31)+Base!R59+C$4*Base!R60+Base!R62+Base!R63 -> 82288.67 | R15: =$A$5*Base!S58*(1-Base!$B$31)+Base!S59+C$4*Base!S60+Base!S62+Base!S63 -> 0 | S15: =$A$5*Base!T58*(1-Base!$B$31)+Base!T59+C$4*Base!T60+Base!T62+Base!T63 -> 0 | T15: =$A$5*Base!U58*(1-Base!$B$31)+Base!U59+C$4*Base!U60+Base!U62+Base!U63 -> 0 | U15: =$A$5*Base!V58*(1-Base!$B$31)+Base!V59+C$4*Base!V60+Base!V62+Base!V63 -> 0 | V15: =$A$5*Base!W58*(1-Base!$B$31)+Base!W59+C$4*Base!W60+Base!W62+Base!W63 -> 0
A16: ="Indtægt "&TEXT($A$5,"0%")&" / investering "&TEXT(D$4,"0%") -> Indtægt 70% / investering 90% | B16: =Base!C65*D$4 -> -5625000 | C16: =$A$5*Base!D58*(1-Base!$B$31)+Base!D59+D$4*Base!D60+Base!D62+Base!D63 -> 261000.22 | D16: =$A$5*Base!E58*(1-Base!$B$31)+Base!E59+D$4*Base!E60+Base!E62+Base!E63 -> 246396.18 | E16: =$A$5*Base!F58*(1-Base!$B$31)+Base!F59+D$4*Base!F60+Base!F62+Base!F63 -> 231932.08 | F16: =$A$5*Base!G58*(1-Base!$B$31)+Base!G59+D$4*Base!G60+Base!G62+Base!G63 -> 217600.32 | G16: =$A$5*Base!H58*(1-Base!$B$31)+Base!H59+D$4*Base!H60+Base!H62+Base!H63 -> 203393.43 | H16: =$A$5*Base!I58*(1-Base!$B$31)+Base!I59+D$4*Base!I60+Base!I62+Base!I63 -> 189304.08 | I16: =$A$5*Base!J58*(1-Base!$B$31)+Base!J59+D$4*Base!J60+Base!J62+Base!J63 -> 175325.07 | J16: =$A$5*Base!K58*(1-Base!$B$31)+Base!K59+D$4*Base!K60+Base!K62+Base!K63 -> 161449.33 | K16: =$A$5*Base!L58*(1-Base!$B$31)+Base!L59+D$4*Base!L60+Base!L62+Base!L63 -> 147669.89 | L16: =$A$5*Base!M58*(1-Base!$B$31)+Base!M59+D$4*Base!M60+Base!M62+Base!M63 -> 133979.9 | M16: =$A$5*Base!N58*(1-Base!$B$31)+Base!N59+D$4*Base!N60+Base!N62+Base!N63 -> 120372.61 | N16: =$A$5*Base!O58*(1-Base!$B$31)+Base!O59+D$4*Base!O60+Base!O62+Base!O63 -> 106841.38 | O16: =$A$5*Base!P58*(1-Base!$B$31)+Base!P59+D$4*Base!P60+Base!P62+Base!P63 -> 93379.639 | P16: =$A$5*Base!Q58*(1-Base!$B$31)+Base!Q59+D$4*Base!Q60+Base!Q62+Base!Q63 -> 79980.944 | Q16: =$A$5*Base!R58*(1-Base!$B$31)+Base!R59+D$4*Base!R60+Base!R62+Base!R63 -> 66638.913 | R16: =$A$5*Base!S58*(1-Base!$B$31)+Base!S59+D$4*Base!S60+Base!S62+Base!S63 -> 0 | S16: =$A$5*Base!T58*(1-Base!$B$31)+Base!T59+D$4*Base!T60+Base!T62+Base!T63 -> 0 | T16: =$A$5*Base!U58*(1-Base!$B$31)+Base!U59+D$4*Base!U60+Base!U62+Base!U63 -> 0 | U16: =$A$5*Base!V58*(1-Base!$B$31)+Base!V59+D$4*Base!V60+Base!V62+Base!V63 -> 0 | V16: =$A$5*Base!W58*(1-Base!$B$31)+Base!W59+D$4*Base!W60+Base!W62+Base!W63 -> 0
A17: ="Indtægt "&TEXT($A$5,"0%")&" / investering "&TEXT(E$4,"0%") -> Indtægt 70% / investering 100% | B17: =Base!C65*E$4 -> -6250000 | C17: =$A$5*Base!D58*(1-Base!$B$31)+Base!D59+E$4*Base!D60+Base!D62+Base!D63 -> 249139.66 | D17: =$A$5*Base!E58*(1-Base!$B$31)+Base!E59+E$4*Base!E60+Base!E62+Base!E63 -> 234298.41 | E17: =$A$5*Base!F58*(1-Base!$B$31)+Base!F59+E$4*Base!F60+Base!F62+Base!F63 -> 219592.36 | F17: =$A$5*Base!G58*(1-Base!$B$31)+Base!G59+E$4*Base!G60+Base!G62+Base!G63 -> 205013.8 | G17: =$A$5*Base!H58*(1-Base!$B$31)+Base!H59+E$4*Base!H60+Base!H62+Base!H63 -> 190555.17 | H17: =$A$5*Base!I58*(1-Base!$B$31)+Base!I59+E$4*Base!I60+Base!I62+Base!I63 -> 176209.06 | I17: =$A$5*Base!J58*(1-Base!$B$31)+Base!J59+E$4*Base!J60+Base!J62+Base!J63 -> 161968.16 | J17: =$A$5*Base!K58*(1-Base!$B$31)+Base!K59+E$4*Base!K60+Base!K62+Base!K63 -> 147825.28 | K17: =$A$5*Base!L58*(1-Base!$B$31)+Base!L59+E$4*Base!L60+Base!L62+Base!L63 -> 133773.36 | L17: =$A$5*Base!M58*(1-Base!$B$31)+Base!M59+E$4*Base!M60+Base!M62+Base!M63 -> 119805.44 | M17: =$A$5*Base!N58*(1-Base!$B$31)+Base!N59+E$4*Base!N60+Base!N62+Base!N63 -> 105914.66 | N17: =$A$5*Base!O58*(1-Base!$B$31)+Base!O59+E$4*Base!O60+Base!O62+Base!O63 -> 92094.259 | O17: =$A$5*Base!P58*(1-Base!$B$31)+Base!P59+E$4*Base!P60+Base!P62+Base!P63 -> 78337.581 | P17: =$A$5*Base!Q58*(1-Base!$B$31)+Base!Q59+E$4*Base!Q60+Base!Q62+Base!Q63 -> 64638.045 | Q17: =$A$5*Base!R58*(1-Base!$B$31)+Base!R59+E$4*Base!R60+Base!R62+Base!R63 -> 50989.156 | R17: =$A$5*Base!S58*(1-Base!$B$31)+Base!S59+E$4*Base!S60+Base!S62+Base!S63 -> 0 | S17: =$A$5*Base!T58*(1-Base!$B$31)+Base!T59+E$4*Base!T60+Base!T62+Base!T63 -> 0 | T17: =$A$5*Base!U58*(1-Base!$B$31)+Base!U59+E$4*Base!U60+Base!U62+Base!U63 -> 0 | U17: =$A$5*Base!V58*(1-Base!$B$31)+Base!V59+E$4*Base!V60+Base!V62+Base!V63 -> 0 | V17: =$A$5*Base!W58*(1-Base!$B$31)+Base!W59+E$4*Base!W60+Base!W62+Base!W63 -> 0
A18: ="Indtægt "&TEXT($A$5,"0%")&" / investering "&TEXT(F$4,"0%") -> Indtægt 70% / investering 110% | B18: =Base!C65*F$4 -> -6875000 | C18: =$A$5*Base!D58*(1-Base!$B$31)+Base!D59+F$4*Base!D60+Base!D62+Base!D63 -> 237279.1 | D18: =$A$5*Base!E58*(1-Base!$B$31)+Base!E59+F$4*Base!E60+Base!E62+Base!E63 -> 222200.64 | E18: =$A$5*Base!F58*(1-Base!$B$31)+Base!F59+F$4*Base!F60+Base!F62+Base!F63 -> 207252.63 | F18: =$A$5*Base!G58*(1-Base!$B$31)+Base!G59+F$4*Base!G60+Base!G62+Base!G63 -> 192427.28 | G18: =$A$5*Base!H58*(1-Base!$B$31)+Base!H59+F$4*Base!H60+Base!H62+Base!H63 -> 177716.92 | H18: =$A$5*Base!I58*(1-Base!$B$31)+Base!I59+F$4*Base!I60+Base!I62+Base!I63 -> 163114.04 | I18: =$A$5*Base!J58*(1-Base!$B$31)+Base!J59+F$4*Base!J60+Base!J62+Base!J63 -> 148611.24 | J18: =$A$5*Base!K58*(1-Base!$B$31)+Base!K59+F$4*Base!K60+Base!K62+Base!K63 -> 134201.22 | K18: =$A$5*Base!L58*(1-Base!$B$31)+Base!L59+F$4*Base!L60+Base!L62+Base!L63 -> 119876.82 | L18: =$A$5*Base!M58*(1-Base!$B$31)+Base!M59+F$4*Base!M60+Base!M62+Base!M63 -> 105630.97 | M18: =$A$5*Base!N58*(1-Base!$B$31)+Base!N59+F$4*Base!N60+Base!N62+Base!N63 -> 91456.7 | N18: =$A$5*Base!O58*(1-Base!$B$31)+Base!O59+F$4*Base!O60+Base!O62+Base!O63 -> 77347.144 | O18: =$A$5*Base!P58*(1-Base!$B$31)+Base!P59+F$4*Base!P60+Base!P62+Base!P63 -> 63295.523 | P18: =$A$5*Base!Q58*(1-Base!$B$31)+Base!Q59+F$4*Base!Q60+Base!Q62+Base!Q63 -> 49295.146 | Q18: =$A$5*Base!R58*(1-Base!$B$31)+Base!R59+F$4*Base!R60+Base!R62+Base!R63 -> 35339.399 | R18: =$A$5*Base!S58*(1-Base!$B$31)+Base!S59+F$4*Base!S60+Base!S62+Base!S63 -> 0 | S18: =$A$5*Base!T58*(1-Base!$B$31)+Base!T59+F$4*Base!T60+Base!T62+Base!T63 -> 0 | T18: =$A$5*Base!U58*(1-Base!$B$31)+Base!U59+F$4*Base!U60+Base!U62+Base!U63 -> 0 | U18: =$A$5*Base!V58*(1-Base!$B$31)+Base!V59+F$4*Base!V60+Base!V62+Base!V63 -> 0 | V18: =$A$5*Base!W58*(1-Base!$B$31)+Base!W59+F$4*Base!W60+Base!W62+Base!W63 -> 0
A19: ="Indtægt "&TEXT($A$5,"0%")&" / investering "&TEXT(G$4,"0%") -> Indtægt 70% / investering 120% | B19: =Base!C65*G$4 -> -7500000 | C19: =$A$5*Base!D58*(1-Base!$B$31)+Base!D59+G$4*Base!D60+Base!D62+Base!D63 -> 225418.54 | D19: =$A$5*Base!E58*(1-Base!$B$31)+Base!E59+G$4*Base!E60+Base!E62+Base!E63 -> 210102.87 | E19: =$A$5*Base!F58*(1-Base!$B$31)+Base!F59+G$4*Base!F60+Base!F62+Base!F63 -> 194912.9 | F19: =$A$5*Base!G58*(1-Base!$B$31)+Base!G59+G$4*Base!G60+Base!G62+Base!G63 -> 179840.75 | G19: =$A$5*Base!H58*(1-Base!$B$31)+Base!H59+G$4*Base!H60+Base!H62+Base!H63 -> 164878.67 | H19: =$A$5*Base!I58*(1-Base!$B$31)+Base!I59+G$4*Base!I60+Base!I62+Base!I63 -> 150019.03 | I19: =$A$5*Base!J58*(1-Base!$B$31)+Base!J59+G$4*Base!J60+Base!J62+Base!J63 -> 135254.32 | J19: =$A$5*Base!K58*(1-Base!$B$31)+Base!K59+G$4*Base!K60+Base!K62+Base!K63 -> 120577.17 | K19: =$A$5*Base!L58*(1-Base!$B$31)+Base!L59+G$4*Base!L60+Base!L62+Base!L63 -> 105980.29 | L19: =$A$5*Base!M58*(1-Base!$B$31)+Base!M59+G$4*Base!M60+Base!M62+Base!M63 -> 91456.502 | M19: =$A$5*Base!N58*(1-Base!$B$31)+Base!N59+G$4*Base!N60+Base!N62+Base!N63 -> 76998.743 | N19: =$A$5*Base!O58*(1-Base!$B$31)+Base!O59+G$4*Base!O60+Base!O62+Base!O63 -> 62600.028 | O19: =$A$5*Base!P58*(1-Base!$B$31)+Base!P59+G$4*Base!P60+Base!P62+Base!P63 -> 48253.466 | P19: =$A$5*Base!Q58*(1-Base!$B$31)+Base!Q59+G$4*Base!Q60+Base!Q62+Base!Q63 -> 33952.247 | Q19: =$A$5*Base!R58*(1-Base!$B$31)+Base!R59+G$4*Base!R60+Base!R62+Base!R63 -> 19689.642 | R19: =$A$5*Base!S58*(1-Base!$B$31)+Base!S59+G$4*Base!S60+Base!S62+Base!S63 -> 0 | S19: =$A$5*Base!T58*(1-Base!$B$31)+Base!T59+G$4*Base!T60+Base!T62+Base!T63 -> 0 | T19: =$A$5*Base!U58*(1-Base!$B$31)+Base!U59+G$4*Base!U60+Base!U62+Base!U63 -> 0 | U19: =$A$5*Base!V58*(1-Base!$B$31)+Base!V59+G$4*Base!V60+Base!V62+Base!V63 -> 0 | V19: =$A$5*Base!W58*(1-Base!$B$31)+Base!W59+G$4*Base!W60+Base!W62+Base!W63 -> 0
A20: ="Indtægt "&TEXT($A$6,"0%")&" / investering "&TEXT(B$4,"0%") -> Indtægt 85% / investering 60% | B20: =Base!C65*B$4 -> -3750000 | C20: =$A$6*Base!D58*(1-Base!$B$31)+Base!D59+B$4*Base!D60+Base!D62+Base!D63 -> 435328.61 | D20: =$A$6*Base!E58*(1-Base!$B$31)+Base!E59+B$4*Base!E60+Base!E62+Base!E63 -> 419195.08 | E20: =$A$6*Base!F58*(1-Base!$B$31)+Base!F59+B$4*Base!F60+Base!F62+Base!F63 -> 403263.78 | F20: =$A$6*Base!G58*(1-Base!$B$31)+Base!G59+B$4*Base!G60+Base!G62+Base!G63 -> 387526.11 | G20: =$A$6*Base!H58*(1-Base!$B$31)+Base!H59+B$4*Base!H60+Base!H62+Base!H63 -> 371973.69 | H20: =$A$6*Base!I58*(1-Base!$B$31)+Base!I59+B$4*Base!I60+Base!I62+Base!I63 -> 356598.29 | I20: =$A$6*Base!J58*(1-Base!$B$31)+Base!J59+B$4*Base!J60+Base!J62+Base!J63 -> 341391.84 | J20: =$A$6*Base!K58*(1-Base!$B$31)+Base!K59+B$4*Base!K60+Base!K62+Base!K63 -> 326346.46 | K20: =$A$6*Base!L58*(1-Base!$B$31)+Base!L59+B$4*Base!L60+Base!L62+Base!L63 -> 311454.39 | L20: =$A$6*Base!M58*(1-Base!$B$31)+Base!M59+B$4*Base!M60+Base!M62+Base!M63 -> 296708.04 | M20: =$A$6*Base!N58*(1-Base!$B$31)+Base!N59+B$4*Base!N60+Base!N62+Base!N63 -> 282099.97 | N20: =$A$6*Base!O58*(1-Base!$B$31)+Base!O59+B$4*Base!O60+Base!O62+Base!O63 -> 267622.86 | O20: =$A$6*Base!P58*(1-Base!$B$31)+Base!P59+B$4*Base!P60+Base!P62+Base!P63 -> 253269.52 | P20: =$A$6*Base!Q58*(1-Base!$B$31)+Base!Q59+B$4*Base!Q60+Base!Q62+Base!Q63 -> 239032.89 | Q20: =$A$6*Base!R58*(1-Base!$B$31)+Base!R59+B$4*Base!R60+Base!R62+Base!R63 -> 224906.05 | R20: =$A$6*Base!S58*(1-Base!$B$31)+Base!S59+B$4*Base!S60+Base!S62+Base!S63 -> 0 | S20: =$A$6*Base!T58*(1-Base!$B$31)+Base!T59+B$4*Base!T60+Base!T62+Base!T63 -> 0 | T20: =$A$6*Base!U58*(1-Base!$B$31)+Base!U59+B$4*Base!U60+Base!U62+Base!U63 -> 0 | U20: =$A$6*Base!V58*(1-Base!$B$31)+Base!V59+B$4*Base!V60+Base!V62+Base!V63 -> 0 | V20: =$A$6*Base!W58*(1-Base!$B$31)+Base!W59+B$4*Base!W60+Base!W62+Base!W63 -> 0
A21: ="Indtægt "&TEXT($A$6,"0%")&" / investering "&TEXT(C$4,"0%") -> Indtægt 85% / investering 80% | B21: =Base!C65*C$4 -> -5000000 | C21: =$A$6*Base!D58*(1-Base!$B$31)+Base!D59+C$4*Base!D60+Base!D62+Base!D63 -> 411607.49 | D21: =$A$6*Base!E58*(1-Base!$B$31)+Base!E59+C$4*Base!E60+Base!E62+Base!E63 -> 394999.54 | E21: =$A$6*Base!F58*(1-Base!$B$31)+Base!F59+C$4*Base!F60+Base!F62+Base!F63 -> 378584.32 | F21: =$A$6*Base!G58*(1-Base!$B$31)+Base!G59+C$4*Base!G60+Base!G62+Base!G63 -> 362353.07 | G21: =$A$6*Base!H58*(1-Base!$B$31)+Base!H59+C$4*Base!H60+Base!H62+Base!H63 -> 346297.19 | H21: =$A$6*Base!I58*(1-Base!$B$31)+Base!I59+C$4*Base!I60+Base!I62+Base!I63 -> 330408.26 | I21: =$A$6*Base!J58*(1-Base!$B$31)+Base!J59+C$4*Base!J60+Base!J62+Base!J63 -> 314678.01 | J21: =$A$6*Base!K58*(1-Base!$B$31)+Base!K59+C$4*Base!K60+Base!K62+Base!K63 -> 299098.35 | K21: =$A$6*Base!L58*(1-Base!$B$31)+Base!L59+C$4*Base!L60+Base!L62+Base!L63 -> 283661.32 | L21: =$A$6*Base!M58*(1-Base!$B$31)+Base!M59+C$4*Base!M60+Base!M62+Base!M63 -> 268359.11 | M21: =$A$6*Base!N58*(1-Base!$B$31)+Base!N59+C$4*Base!N60+Base!N62+Base!N63 -> 253184.06 | N21: =$A$6*Base!O58*(1-Base!$B$31)+Base!O59+C$4*Base!O60+Base!O62+Base!O63 -> 238128.63 | O21: =$A$6*Base!P58*(1-Base!$B$31)+Base!P59+C$4*Base!P60+Base!P62+Base!P63 -> 223185.4 | P21: =$A$6*Base!Q58*(1-Base!$B$31)+Base!Q59+C$4*Base!Q60+Base!Q62+Base!Q63 -> 208347.09 | Q21: =$A$6*Base!R58*(1-Base!$B$31)+Base!R59+C$4*Base!R60+Base!R62+Base!R63 -> 193606.53 | R21: =$A$6*Base!S58*(1-Base!$B$31)+Base!S59+C$4*Base!S60+Base!S62+Base!S63 -> 0 | S21: =$A$6*Base!T58*(1-Base!$B$31)+Base!T59+C$4*Base!T60+Base!T62+Base!T63 -> 0 | T21: =$A$6*Base!U58*(1-Base!$B$31)+Base!U59+C$4*Base!U60+Base!U62+Base!U63 -> 0 | U21: =$A$6*Base!V58*(1-Base!$B$31)+Base!V59+C$4*Base!V60+Base!V62+Base!V63 -> 0 | V21: =$A$6*Base!W58*(1-Base!$B$31)+Base!W59+C$4*Base!W60+Base!W62+Base!W63 -> 0
A22: ="Indtægt "&TEXT($A$6,"0%")&" / investering "&TEXT(D$4,"0%") -> Indtægt 85% / investering 90% | B22: =Base!C65*D$4 -> -5625000 | C22: =$A$6*Base!D58*(1-Base!$B$31)+Base!D59+D$4*Base!D60+Base!D62+Base!D63 -> 399746.93 | D22: =$A$6*Base!E58*(1-Base!$B$31)+Base!E59+D$4*Base!E60+Base!E62+Base!E63 -> 382901.77 | E22: =$A$6*Base!F58*(1-Base!$B$31)+Base!F59+D$4*Base!F60+Base!F62+Base!F63 -> 366244.6 | F22: =$A$6*Base!G58*(1-Base!$B$31)+Base!G59+D$4*Base!G60+Base!G62+Base!G63 -> 349766.55 | G22: =$A$6*Base!H58*(1-Base!$B$31)+Base!H59+D$4*Base!H60+Base!H62+Base!H63 -> 333458.94 | H22: =$A$6*Base!I58*(1-Base!$B$31)+Base!I59+D$4*Base!I60+Base!I62+Base!I63 -> 317313.24 | I22: =$A$6*Base!J58*(1-Base!$B$31)+Base!J59+D$4*Base!J60+Base!J62+Base!J63 -> 301321.09 | J22: =$A$6*Base!K58*(1-Base!$B$31)+Base!K59+D$4*Base!K60+Base!K62+Base!K63 -> 285474.29 | K22: =$A$6*Base!L58*(1-Base!$B$31)+Base!L59+D$4*Base!L60+Base!L62+Base!L63 -> 269764.78 | L22: =$A$6*Base!M58*(1-Base!$B$31)+Base!M59+D$4*Base!M60+Base!M62+Base!M63 -> 254184.64 | M22: =$A$6*Base!N58*(1-Base!$B$31)+Base!N59+D$4*Base!N60+Base!N62+Base!N63 -> 238726.1 | N22: =$A$6*Base!O58*(1-Base!$B$31)+Base!O59+D$4*Base!O60+Base!O62+Base!O63 -> 223381.51 | O22: =$A$6*Base!P58*(1-Base!$B$31)+Base!P59+D$4*Base!P60+Base!P62+Base!P63 -> 208143.34 | P22: =$A$6*Base!Q58*(1-Base!$B$31)+Base!Q59+D$4*Base!Q60+Base!Q62+Base!Q63 -> 193004.19 | Q22: =$A$6*Base!R58*(1-Base!$B$31)+Base!R59+D$4*Base!R60+Base!R62+Base!R63 -> 177956.77 | R22: =$A$6*Base!S58*(1-Base!$B$31)+Base!S59+D$4*Base!S60+Base!S62+Base!S63 -> 0 | S22: =$A$6*Base!T58*(1-Base!$B$31)+Base!T59+D$4*Base!T60+Base!T62+Base!T63 -> 0 | T22: =$A$6*Base!U58*(1-Base!$B$31)+Base!U59+D$4*Base!U60+Base!U62+Base!U63 -> 0 | U22: =$A$6*Base!V58*(1-Base!$B$31)+Base!V59+D$4*Base!V60+Base!V62+Base!V63 -> 0 | V22: =$A$6*Base!W58*(1-Base!$B$31)+Base!W59+D$4*Base!W60+Base!W62+Base!W63 -> 0
A23: ="Indtægt "&TEXT($A$6,"0%")&" / investering "&TEXT(E$4,"0%") -> Indtægt 85% / investering 100% | B23: =Base!C65*E$4 -> -6250000 | C23: =$A$6*Base!D58*(1-Base!$B$31)+Base!D59+E$4*Base!D60+Base!D62+Base!D63 -> 387886.37 | D23: =$A$6*Base!E58*(1-Base!$B$31)+Base!E59+E$4*Base!E60+Base!E62+Base!E63 -> 370804 | E23: =$A$6*Base!F58*(1-Base!$B$31)+Base!F59+E$4*Base!F60+Base!F62+Base!F63 -> 353904.87 | F23: =$A$6*Base!G58*(1-Base!$B$31)+Base!G59+E$4*Base!G60+Base!G62+Base!G63 -> 337180.03 | G23: =$A$6*Base!H58*(1-Base!$B$31)+Base!H59+E$4*Base!H60+Base!H62+Base!H63 -> 320620.69 | H23: =$A$6*Base!I58*(1-Base!$B$31)+Base!I59+E$4*Base!I60+Base!I62+Base!I63 -> 304218.22 | I23: =$A$6*Base!J58*(1-Base!$B$31)+Base!J59+E$4*Base!J60+Base!J62+Base!J63 -> 287964.18 | J23: =$A$6*Base!K58*(1-Base!$B$31)+Base!K59+E$4*Base!K60+Base!K62+Base!K63 -> 271850.24 | K23: =$A$6*Base!L58*(1-Base!$B$31)+Base!L59+E$4*Base!L60+Base!L62+Base!L63 -> 255868.24 | L23: =$A$6*Base!M58*(1-Base!$B$31)+Base!M59+E$4*Base!M60+Base!M62+Base!M63 -> 240010.18 | M23: =$A$6*Base!N58*(1-Base!$B$31)+Base!N59+E$4*Base!N60+Base!N62+Base!N63 -> 224268.15 | N23: =$A$6*Base!O58*(1-Base!$B$31)+Base!O59+E$4*Base!O60+Base!O62+Base!O63 -> 208634.39 | O23: =$A$6*Base!P58*(1-Base!$B$31)+Base!P59+E$4*Base!P60+Base!P62+Base!P63 -> 193101.28 | P23: =$A$6*Base!Q58*(1-Base!$B$31)+Base!Q59+E$4*Base!Q60+Base!Q62+Base!Q63 -> 177661.3 | Q23: =$A$6*Base!R58*(1-Base!$B$31)+Base!R59+E$4*Base!R60+Base!R62+Base!R63 -> 162307.02 | R23: =$A$6*Base!S58*(1-Base!$B$31)+Base!S59+E$4*Base!S60+Base!S62+Base!S63 -> 0 | S23: =$A$6*Base!T58*(1-Base!$B$31)+Base!T59+E$4*Base!T60+Base!T62+Base!T63 -> 0 | T23: =$A$6*Base!U58*(1-Base!$B$31)+Base!U59+E$4*Base!U60+Base!U62+Base!U63 -> 0 | U23: =$A$6*Base!V58*(1-Base!$B$31)+Base!V59+E$4*Base!V60+Base!V62+Base!V63 -> 0 | V23: =$A$6*Base!W58*(1-Base!$B$31)+Base!W59+E$4*Base!W60+Base!W62+Base!W63 -> 0
A24: ="Indtægt "&TEXT($A$6,"0%")&" / investering "&TEXT(F$4,"0%") -> Indtægt 85% / investering 110% | B24: =Base!C65*F$4 -> -6875000 | C24: =$A$6*Base!D58*(1-Base!$B$31)+Base!D59+F$4*Base!D60+Base!D62+Base!D63 -> 376025.81 | D24: =$A$6*Base!E58*(1-Base!$B$31)+Base!E59+F$4*Base!E60+Base!E62+Base!E63 -> 358706.22 | E24: =$A$6*Base!F58*(1-Base!$B$31)+Base!F59+F$4*Base!F60+Base!F62+Base!F63 -> 341565.14 | F24: =$A$6*Base!G58*(1-Base!$B$31)+Base!G59+F$4*Base!G60+Base!G62+Base!G63 -> 324593.51 | G24: =$A$6*Base!H58*(1-Base!$B$31)+Base!H59+F$4*Base!H60+Base!H62+Base!H63 -> 307782.44 | H24: =$A$6*Base!I58*(1-Base!$B$31)+Base!I59+F$4*Base!I60+Base!I62+Base!I63 -> 291123.21 | I24: =$A$6*Base!J58*(1-Base!$B$31)+Base!J59+F$4*Base!J60+Base!J62+Base!J63 -> 274607.26 | J24: =$A$6*Base!K58*(1-Base!$B$31)+Base!K59+F$4*Base!K60+Base!K62+Base!K63 -> 258226.18 | K24: =$A$6*Base!L58*(1-Base!$B$31)+Base!L59+F$4*Base!L60+Base!L62+Base!L63 -> 241971.71 | L24: =$A$6*Base!M58*(1-Base!$B$31)+Base!M59+F$4*Base!M60+Base!M62+Base!M63 -> 225835.71 | M24: =$A$6*Base!N58*(1-Base!$B$31)+Base!N59+F$4*Base!N60+Base!N62+Base!N63 -> 209810.19 | N24: =$A$6*Base!O58*(1-Base!$B$31)+Base!O59+F$4*Base!O60+Base!O62+Base!O63 -> 193887.28 | O24: =$A$6*Base!P58*(1-Base!$B$31)+Base!P59+F$4*Base!P60+Base!P62+Base!P63 -> 178059.23 | P24: =$A$6*Base!Q58*(1-Base!$B$31)+Base!Q59+F$4*Base!Q60+Base!Q62+Base!Q63 -> 162318.4 | Q24: =$A$6*Base!R58*(1-Base!$B$31)+Base!R59+F$4*Base!R60+Base!R62+Base!R63 -> 146657.26 | R24: =$A$6*Base!S58*(1-Base!$B$31)+Base!S59+F$4*Base!S60+Base!S62+Base!S63 -> 0 | S24: =$A$6*Base!T58*(1-Base!$B$31)+Base!T59+F$4*Base!T60+Base!T62+Base!T63 -> 0 | T24: =$A$6*Base!U58*(1-Base!$B$31)+Base!U59+F$4*Base!U60+Base!U62+Base!U63 -> 0 | U24: =$A$6*Base!V58*(1-Base!$B$31)+Base!V59+F$4*Base!V60+Base!V62+Base!V63 -> 0 | V24: =$A$6*Base!W58*(1-Base!$B$31)+Base!W59+F$4*Base!W60+Base!W62+Base!W63 -> 0
A25: ="Indtægt "&TEXT($A$6,"0%")&" / investering "&TEXT(G$4,"0%") -> Indtægt 85% / investering 120% | B25: =Base!C65*G$4 -> -7500000 | C25: =$A$6*Base!D58*(1-Base!$B$31)+Base!D59+G$4*Base!D60+Base!D62+Base!D63 -> 364165.25 | D25: =$A$6*Base!E58*(1-Base!$B$31)+Base!E59+G$4*Base!E60+Base!E62+Base!E63 -> 346608.45 | E25: =$A$6*Base!F58*(1-Base!$B$31)+Base!F59+G$4*Base!F60+Base!F62+Base!F63 -> 329225.42 | F25: =$A$6*Base!G58*(1-Base!$B$31)+Base!G59+G$4*Base!G60+Base!G62+Base!G63 -> 312006.99 | G25: =$A$6*Base!H58*(1-Base!$B$31)+Base!H59+G$4*Base!H60+Base!H62+Base!H63 -> 294944.18 | H25: =$A$6*Base!I58*(1-Base!$B$31)+Base!I59+G$4*Base!I60+Base!I62+Base!I63 -> 278028.19 | I25: =$A$6*Base!J58*(1-Base!$B$31)+Base!J59+G$4*Base!J60+Base!J62+Base!J63 -> 261250.34 | J25: =$A$6*Base!K58*(1-Base!$B$31)+Base!K59+G$4*Base!K60+Base!K62+Base!K63 -> 244602.13 | K25: =$A$6*Base!L58*(1-Base!$B$31)+Base!L59+G$4*Base!L60+Base!L62+Base!L63 -> 228075.17 | L25: =$A$6*Base!M58*(1-Base!$B$31)+Base!M59+G$4*Base!M60+Base!M62+Base!M63 -> 211661.24 | M25: =$A$6*Base!N58*(1-Base!$B$31)+Base!N59+G$4*Base!N60+Base!N62+Base!N63 -> 195352.23 | N25: =$A$6*Base!O58*(1-Base!$B$31)+Base!O59+G$4*Base!O60+Base!O62+Base!O63 -> 179140.16 | O25: =$A$6*Base!P58*(1-Base!$B$31)+Base!P59+G$4*Base!P60+Base!P62+Base!P63 -> 163017.17 | P25: =$A$6*Base!Q58*(1-Base!$B$31)+Base!Q59+G$4*Base!Q60+Base!Q62+Base!Q63 -> 146975.5 | Q25: =$A$6*Base!R58*(1-Base!$B$31)+Base!R59+G$4*Base!R60+Base!R62+Base!R63 -> 131007.5 | R25: =$A$6*Base!S58*(1-Base!$B$31)+Base!S59+G$4*Base!S60+Base!S62+Base!S63 -> 0 | S25: =$A$6*Base!T58*(1-Base!$B$31)+Base!T59+G$4*Base!T60+Base!T62+Base!T63 -> 0 | T25: =$A$6*Base!U58*(1-Base!$B$31)+Base!U59+G$4*Base!U60+Base!U62+Base!U63 -> 0 | U25: =$A$6*Base!V58*(1-Base!$B$31)+Base!V59+G$4*Base!V60+Base!V62+Base!V63 -> 0 | V25: =$A$6*Base!W58*(1-Base!$B$31)+Base!W59+G$4*Base!W60+Base!W62+Base!W63 -> 0
A26: ="Indtægt "&TEXT($A$7,"0%")&" / investering "&TEXT(B$4,"0%") -> Indtægt 100% / investering 60% | B26: =Base!C65*B$4 -> -3750000 | C26: =$A$7*Base!D58*(1-Base!$B$31)+Base!D59+B$4*Base!D60+Base!D62+Base!D63 -> 574075.33 | D26: =$A$7*Base!E58*(1-Base!$B$31)+Base!E59+B$4*Base!E60+Base!E62+Base!E63 -> 555700.66 | E26: =$A$7*Base!F58*(1-Base!$B$31)+Base!F59+B$4*Base!F60+Base!F62+Base!F63 -> 537576.29 | F26: =$A$7*Base!G58*(1-Base!$B$31)+Base!G59+B$4*Base!G60+Base!G62+Base!G63 -> 519692.35 | G26: =$A$7*Base!H58*(1-Base!$B$31)+Base!H59+B$4*Base!H60+Base!H62+Base!H63 -> 502039.21 | H26: =$A$7*Base!I58*(1-Base!$B$31)+Base!I59+B$4*Base!I60+Base!I62+Base!I63 -> 484607.45 | I26: =$A$7*Base!J58*(1-Base!$B$31)+Base!J59+B$4*Base!J60+Base!J62+Base!J63 -> 467387.86 | J26: =$A$7*Base!K58*(1-Base!$B$31)+Base!K59+B$4*Base!K60+Base!K62+Base!K63 -> 450371.42 | K26: =$A$7*Base!L58*(1-Base!$B$31)+Base!L59+B$4*Base!L60+Base!L62+Base!L63 -> 433549.27 | L26: =$A$7*Base!M58*(1-Base!$B$31)+Base!M59+B$4*Base!M60+Base!M62+Base!M63 -> 416912.78 | M26: =$A$7*Base!N58*(1-Base!$B$31)+Base!N59+B$4*Base!N60+Base!N62+Base!N63 -> 400453.46 | N26: =$A$7*Base!O58*(1-Base!$B$31)+Base!O59+B$4*Base!O60+Base!O62+Base!O63 -> 384162.99 | O26: =$A$7*Base!P58*(1-Base!$B$31)+Base!P59+B$4*Base!P60+Base!P62+Base!P63 -> 368033.22 | P26: =$A$7*Base!Q58*(1-Base!$B$31)+Base!Q59+B$4*Base!Q60+Base!Q62+Base!Q63 -> 352056.14 | Q26: =$A$7*Base!R58*(1-Base!$B$31)+Base!R59+B$4*Base!R60+Base!R62+Base!R63 -> 336223.91 | R26: =$A$7*Base!S58*(1-Base!$B$31)+Base!S59+B$4*Base!S60+Base!S62+Base!S63 -> 0 | S26: =$A$7*Base!T58*(1-Base!$B$31)+Base!T59+B$4*Base!T60+Base!T62+Base!T63 -> 0 | T26: =$A$7*Base!U58*(1-Base!$B$31)+Base!U59+B$4*Base!U60+Base!U62+Base!U63 -> 0 | U26: =$A$7*Base!V58*(1-Base!$B$31)+Base!V59+B$4*Base!V60+Base!V62+Base!V63 -> 0 | V26: =$A$7*Base!W58*(1-Base!$B$31)+Base!W59+B$4*Base!W60+Base!W62+Base!W63 -> 0
A27: ="Indtægt "&TEXT($A$7,"0%")&" / investering "&TEXT(C$4,"0%") -> Indtægt 100% / investering 80% | B27: =Base!C65*C$4 -> -5000000 | C27: =$A$7*Base!D58*(1-Base!$B$31)+Base!D59+C$4*Base!D60+Base!D62+Base!D63 -> 550354.21 | D27: =$A$7*Base!E58*(1-Base!$B$31)+Base!E59+C$4*Base!E60+Base!E62+Base!E63 -> 531505.12 | E27: =$A$7*Base!F58*(1-Base!$B$31)+Base!F59+C$4*Base!F60+Base!F62+Base!F63 -> 512896.83 | F27: =$A$7*Base!G58*(1-Base!$B$31)+Base!G59+C$4*Base!G60+Base!G62+Base!G63 -> 494519.3 | G27: =$A$7*Base!H58*(1-Base!$B$31)+Base!H59+C$4*Base!H60+Base!H62+Base!H63 -> 476362.7 | H27: =$A$7*Base!I58*(1-Base!$B$31)+Base!I59+C$4*Base!I60+Base!I62+Base!I63 -> 458417.42 | I27: =$A$7*Base!J58*(1-Base!$B$31)+Base!J59+C$4*Base!J60+Base!J62+Base!J63 -> 440674.03 | J27: =$A$7*Base!K58*(1-Base!$B$31)+Base!K59+C$4*Base!K60+Base!K62+Base!K63 -> 423123.3 | K27: =$A$7*Base!L58*(1-Base!$B$31)+Base!L59+C$4*Base!L60+Base!L62+Base!L63 -> 405756.2 | L27: =$A$7*Base!M58*(1-Base!$B$31)+Base!M59+C$4*Base!M60+Base!M62+Base!M63 -> 388563.85 | M27: =$A$7*Base!N58*(1-Base!$B$31)+Base!N59+C$4*Base!N60+Base!N62+Base!N63 -> 371537.55 | N27: =$A$7*Base!O58*(1-Base!$B$31)+Base!O59+C$4*Base!O60+Base!O62+Base!O63 -> 354668.76 | O27: =$A$7*Base!P58*(1-Base!$B$31)+Base!P59+C$4*Base!P60+Base!P62+Base!P63 -> 337949.1 | P27: =$A$7*Base!Q58*(1-Base!$B$31)+Base!Q59+C$4*Base!Q60+Base!Q62+Base!Q63 -> 321370.34 | Q27: =$A$7*Base!R58*(1-Base!$B$31)+Base!R59+C$4*Base!R60+Base!R62+Base!R63 -> 304924.39 | R27: =$A$7*Base!S58*(1-Base!$B$31)+Base!S59+C$4*Base!S60+Base!S62+Base!S63 -> 0 | S27: =$A$7*Base!T58*(1-Base!$B$31)+Base!T59+C$4*Base!T60+Base!T62+Base!T63 -> 0 | T27: =$A$7*Base!U58*(1-Base!$B$31)+Base!U59+C$4*Base!U60+Base!U62+Base!U63 -> 0 | U27: =$A$7*Base!V58*(1-Base!$B$31)+Base!V59+C$4*Base!V60+Base!V62+Base!V63 -> 0 | V27: =$A$7*Base!W58*(1-Base!$B$31)+Base!W59+C$4*Base!W60+Base!W62+Base!W63 -> 0
A28: ="Indtægt "&TEXT($A$7,"0%")&" / investering "&TEXT(D$4,"0%") -> Indtægt 100% / investering 90% | B28: =Base!C65*D$4 -> -5625000 | C28: =$A$7*Base!D58*(1-Base!$B$31)+Base!D59+D$4*Base!D60+Base!D62+Base!D63 -> 538493.65 | D28: =$A$7*Base!E58*(1-Base!$B$31)+Base!E59+D$4*Base!E60+Base!E62+Base!E63 -> 519407.35 | E28: =$A$7*Base!F58*(1-Base!$B$31)+Base!F59+D$4*Base!F60+Base!F62+Base!F63 -> 500557.11 | F28: =$A$7*Base!G58*(1-Base!$B$31)+Base!G59+D$4*Base!G60+Base!G62+Base!G63 -> 481932.78 | G28: =$A$7*Base!H58*(1-Base!$B$31)+Base!H59+D$4*Base!H60+Base!H62+Base!H63 -> 463524.45 | H28: =$A$7*Base!I58*(1-Base!$B$31)+Base!I59+D$4*Base!I60+Base!I62+Base!I63 -> 445322.4 | I28: =$A$7*Base!J58*(1-Base!$B$31)+Base!J59+D$4*Base!J60+Base!J62+Base!J63 -> 427317.11 | J28: =$A$7*Base!K58*(1-Base!$B$31)+Base!K59+D$4*Base!K60+Base!K62+Base!K63 -> 409499.25 | K28: =$A$7*Base!L58*(1-Base!$B$31)+Base!L59+D$4*Base!L60+Base!L62+Base!L63 -> 391859.66 | L28: =$A$7*Base!M58*(1-Base!$B$31)+Base!M59+D$4*Base!M60+Base!M62+Base!M63 -> 374389.38 | M28: =$A$7*Base!N58*(1-Base!$B$31)+Base!N59+D$4*Base!N60+Base!N62+Base!N63 -> 357079.59 | N28: =$A$7*Base!O58*(1-Base!$B$31)+Base!O59+D$4*Base!O60+Base!O62+Base!O63 -> 339921.64 | O28: =$A$7*Base!P58*(1-Base!$B$31)+Base!P59+D$4*Base!P60+Base!P62+Base!P63 -> 322907.05 | P28: =$A$7*Base!Q58*(1-Base!$B$31)+Base!Q59+D$4*Base!Q60+Base!Q62+Base!Q63 -> 306027.45 | Q28: =$A$7*Base!R58*(1-Base!$B$31)+Base!R59+D$4*Base!R60+Base!R62+Base!R63 -> 289274.63 | R28: =$A$7*Base!S58*(1-Base!$B$31)+Base!S59+D$4*Base!S60+Base!S62+Base!S63 -> 0 | S28: =$A$7*Base!T58*(1-Base!$B$31)+Base!T59+D$4*Base!T60+Base!T62+Base!T63 -> 0 | T28: =$A$7*Base!U58*(1-Base!$B$31)+Base!U59+D$4*Base!U60+Base!U62+Base!U63 -> 0 | U28: =$A$7*Base!V58*(1-Base!$B$31)+Base!V59+D$4*Base!V60+Base!V62+Base!V63 -> 0 | V28: =$A$7*Base!W58*(1-Base!$B$31)+Base!W59+D$4*Base!W60+Base!W62+Base!W63 -> 0
